Workbook

Sheet 2501_MIS 
A1: Sl No. | B1: Student Name | C1: Student System ID | D1: Student Roll No. | E1: New Section | F1: FastTrack | G1: Status after 2411 | H1: Group | I1: Mentor | J1: Student Email ID | K1: Parent mail id | L1: contact number | M1: Specialization | O1: Status After 2413
A2: 1 | B2: Anutosh Mishra | C2: 2021308861 | D2: 210101102 | E2: B-Tech CSE-VI A | F2: =VLOOKUP('2501_MIS '!C2,'[1]Fast Track '!B:K,10,FALSE) -> #N/A | G2: =VLOOKUP(C2,[2]Sheet7!A:D,4,FALSE) -> Not Promoted | H2: G1 | I2: Ms. Aanchal Vij | J2: 2021308861.anutosh@ug.sharda.ac.in | K2: =VLOOKUP(C2,[3]Sheet1!D:J,6,FALSE) -> 2021308861.ashutoshkumar@pt.sharda.ac.in | L2: =VLOOKUP(D2,[3]Sheet1!E:K,6,FALSE) -> 9936777552 | M2: Computer Science | O2: =VLOOKUP(C2,#REF!,12,FALSE) -> #REF!
A3: 2 | B3: Garv Sharma | C3: 2021529806 | D3: 210101190 | E3: B-Tech CSE-VI A | F3: =VLOOKUP('2501_MIS '!C3,'[1]Fast Track '!B:K,10,FALSE) -> #N/A | G3: =VLOOKUP(C3,[2]Sheet7!A:D,4,FALSE) -> Not Promoted | H3: G1 | I3: Ms. Aanchal Vij | J3: 2021529806.garv@ug.sharda.ac.in | K3: =VLOOKUP(C3,[3]Sheet1!D:J,6,FALSE) -> 2021529806.santosh@pt.sharda.ac.in | L3: =VLOOKUP(D3,[3]Sheet1!E:K,6,FALSE) -> 9711552459 | M3: Computer Science | O3: =VLOOKUP(C3,#REF!,12,FALSE) -> #REF!
A4: 3 | B4: Nandani Chaudhary | C4: 2021828405 | D4: 210101591 | E4: B-Tech CSE-VI A | F4: =VLOOKUP('2501_MIS '!C4,'[1]Fast Track '!B:K,10,FALSE) -> #N/A | G4: =VLOOKUP(C4,[2]Sheet7!A:D,4,FALSE) -> Not Promoted | H4: G1 | I4: Ms. Aanchal Vij | J4: 2021828405.nandani@ug.sharda.ac.in | K4: =VLOOKUP(C4,[3]Sheet1!D:J,6,FALSE) -> 2021828405.ramananda@pt.sharda.ac.in | L4: =VLOOKUP(D4,[3]Sheet1!E:K,6,FALSE) -> 8130538380 | M4: Computer Science | O4: =VLOOKUP(C4,#REF!,12,FALSE) -> #REF!
A5: 4 | B5: Farheen Khan | C5: 2021000009 | D5: 210121021 | E5: B-Tech CSE-VI A | F5: =VLOOKUP('2501_MIS '!C5,'[1]Fast Track '!B:K,10,FALSE) -> #N/A | G5: =VLOOKUP(C5,[2]Sheet7!A:D,4,FALSE) -> Not Promoted | H5: G1 | I5: Ms. Aanchal Vij | J5: 2021000009.farheen@ug.sharda.ac.in | K5: =VLOOKUP(C5,[3]Sheet1!D:J,6,FALSE) -> 2021000009.asad@pt.sharda.ac.in | L5: =VLOOKUP(D5,[3]Sheet1!E:K,6,FALSE) -> 9599543010 | M5: Computer Science | O5: =VLOOKUP(C5,#REF!,12,FALSE) -> #REF!
A6: 5 | B6: Abhiraj Singh | C6: 2022579515 | D6: 2201010023 | E6: B-Tech CSE-VI A | F6: =VLOOKUP('2501_MIS '!C6,'[1]Fast Track '!B:K,10,FALSE) -> #N/A | G6: =VLOOKUP(C6,[2]Sheet7!A:D,4,FALSE) -> Promoted | H6: G1 | I6: Ms. Aanchal Vij | J6: 2022579515.abhiraj@ug.sharda.ac.in | K6: =VLOOKUP(C6,[3]Sheet1!D:J,6,FALSE) -> 2022579515.vijaykumar@pt.sharda.ac.in | L6: =VLOOKUP(D6,[3]Sheet1!E:K,6,FALSE) -> 8826793887 | M6: Computer Science | O6: =VLOOKUP(C6,#REF!,12,FALSE) -> #REF!
A7: 6 | B7: Aman Sinha | C7: 2022534811 | D7: 2201010078 | E7: B-Tech CSE-VI A | F7: =VLOOKUP('2501_MIS '!C7,'[1]Fast Track '!B:K,10,FALSE) -> #N/A | G7: =VLOOKUP(C7,[2]Sheet7!A:D,4,FALSE) -> Promoted | H7: G1 | I7: Ms. Aanchal Vij | J7: 2022534811.aman@ug.sharda.ac.in | K7: =VLOOKUP(C7,[3]Sheet1!D:J,6,FALSE) -> 2022534811.rajeshkumar@pt.sharda.ac.in | L7: =VLOOKUP(D7,[3]Sheet1!E:K,6,FALSE) -> 7319641049 | M7: Computer Science | O7: =VLOOKUP(C7,#REF!,12,FALSE) -> #REF!
A8: 7 | B8: Ansh Shrivastav | C8: 2022475156 | D8: 2201010099 | E8: B-Tech CSE-VI A | F8: =VLOOKUP('2501_MIS '!C8,'[1]Fast Track '!B:K,10,FALSE) -> #N/A | G8: =VLOOKUP(C8,[2]Sheet7!A:D,4,FALSE) -> Promoted | H8: G1 | I8: Ms. Aanchal Vij | J8: 2022475156.ansh@ug.sharda.ac.in | K8: =VLOOKUP(C8,[3]Sheet1!D:J,6,FALSE) -> 2022475156.dhananjay@pt.sharda.ac.in | L8: =VLOOKUP(D8,[3]Sheet1!E:K,6,FALSE) -> 8789919805 | M8: Computer Science | O8: =VLOOKUP(C8,#REF!,12,FALSE) -> #REF!
A9: 8 | B9: Anuj Rawat | C9: 2022394343 | D9: 2201010111 | E9: B-Tech CSE-VI A | F9: =VLOOKUP('2501_MIS '!C9,'[1]Fast Track '!B:K,10,FALSE) -> #N/A | G9: =VLOOKUP(C9,[2]Sheet7!A:D,4,FALSE) -> Promoted | H9: G1 | I9: Ms. Aanchal Vij | J9: 2022394343.anuj@ug.sharda.ac.in | K9: =VLOOKUP(C9,[3]Sheet1!D:J,6,FALSE) -> 2022394343.anandsingh@pt.sharda.ac.in | L9: =VLOOKUP(D9,[3]Sheet1!E:K,6,FALSE) -> 8126133363 | M9: Computer Science | O9: =VLOOKUP(C9,#REF!,12,FALSE) -> #REF!
A10: 9 | B10: Arbaz Ahmed | C10: 2022006308 | D10: 2201010121 | E10: B-Tech CSE-VI A | F10: =VLOOKUP('2501_MIS '!C10,'[1]Fast Track '!B:K,10,FALSE) -> #N/A | G10: =VLOOKUP(C10,[2]Sheet7!A:D,4,FALSE) -> Promoted | H10: G1 | I10: Ms. Aanchal Vij | J10: 2022006308.arbaz@ug.sharda.ac.in | K10: =VLOOKUP(C10,[3]Sheet1!D:J,6,FALSE) -> 2022006308.asad@pt.sharda.ac.in | L10: =VLOOKUP(D10,[3]Sheet1!E:K,6,FALSE) -> 7300577335 | M10: Computer Science | O10: =VLOOKUP(C10,#REF!,12,FALSE) -> #REF!
A11: 10 | B11: Atithi Negi | C11: 2022438604 | D11: 2201010162 | E11: B-Tech CSE-VI A | F11: =VLOOKUP('2501_MIS '!C11,'[1]Fast Track '!B:K,10,FALSE) -> #N/A | G11: =VLOOKUP(C11,[2]Sheet7!A:D,4,FALSE) -> Promoted | H11: G1 | I11: Ms. Aanchal Vij | J11: 2022438604.atithi@ug.sharda.ac.in | K11: =VLOOKUP(C11,[3]Sheet1!D:J,6,FALSE) -> 2022438604.kundansingh@pt.sharda.ac.in | L11: =VLOOKUP(D11,[3]Sheet1!E:K,6,FALSE) -> 8920297350 | M11: Computer Science | O11: =VLOOKUP(C11,#REF!,12,FALSE) -> #REF!
A12: 11 | B12: Basharat Hassan | C12: 2022521926 | D12: 2201010175 | E12: B-Tech CSE-VI A | F12: =VLOOKUP('2501_MIS '!C12,'[1]Fast Track '!B:K,10,FALSE) -> #N/A | G12: =VLOOKUP(C12,[2]Sheet7!A:D,4,FALSE) -> Promoted | H12: G1 | I12: Ms. Aanchal Vij | J12: 2022521926.basharat@ug.sharda.ac.in | K12: =VLOOKUP(C12,[3]Sheet1!D:J,6,FALSE) -> 2022521926.ghulamhassan@pt.sharda.ac.in | L12: =VLOOKUP(D12,[3]Sheet1!E:K,6,FALSE) -> 8899544845 | M12: Computer Science | O12: =VLOOKUP(C12,#REF!,12,FALSE) -> #REF!
A13: 12 | B13: Bhoomi Sharma | C13: 2022325232 | D13: 2201010178 | E13: B-Tech CSE-VI A | F13: =VLOOKUP('2501_MIS '!C13,'[1]Fast Track '!B:K,10,FALSE) -> #N/A | G13: =VLOOKUP(C13,[2]Sheet7!A:D,4,FALSE) -> Promoted | H13: G1 | I13: Ms. Aanchal Vij | J13: 2022325232.bhoomi@ug.sharda.ac.in | K13: =VLOOKUP(C13,[3]Sheet1!D:J,6,FALSE) -> 2022325232.latesuneet@pt.sharda.ac.in | L13: =VLOOKUP(D13,[3]Sheet1!E:K,6,FALSE) -> 9717628588 | M13: Computer Science | O13: =VLOOKUP(C13,#REF!,12,FALSE) -> #REF!
... A59: 58 | B59: Sarthak Sanghai | C59: 2022837427 | D59: 2201010913 | E59: B-Tech CSE-VI A | F59: =VLOOKUP('2501_MIS '!C59,'[1]Fast Track '!B:K,10,FALSE) -> #N/A | G59: =VLOOKUP(C59,[2]Sheet7!A:D,4,FALSE) -> Promoted | H59: G2 | I59: Dr. Himanshu Sharma | J59: 2022837427.sarthak@ug.sharda.ac.in | K59: =VLOOKUP(C59,[3]Sheet1!D:J,6,FALSE) -> 2022837427.kanhaiyalal@pt.sharda.ac.in | L59: =VLOOKUP(D59,[3]Sheet1!E:K,6,FALSE) -> 977 9813003131 | M59: Computer Science | O59: =VLOOKUP(C59,#REF!,12,FALSE) -> #REF!
A60: 59 | B60: Andrew Chingthat Khaigoulen Mate | C60: 2023248088 | D60: 2301017003 | E60: B-Tech CSE-VI A | F60: =VLOOKUP('2501_MIS '!C60,'[1]Fast Track '!B:K,10,FALSE) -> #N/A | G60: =VLOOKUP(C60,[2]Sheet7!A:D,4,FALSE) -> Not Promoted | H60: G2 | I60: Dr. Himanshu Sharma | J60: 2023248088.andrew@ug.sharda.ac.in | K60: =VLOOKUP(C60,[3]Sheet1!D:J,6,FALSE) -> 2023248088.ch@pt.sharda.ac.in | L60: =VLOOKUP(D60,[3]Sheet1!E:K,6,FALSE) -> 9013572298 | M60: Computer Science | N60: Readmitted | O60: =VLOOKUP(C60,#REF!,12,FALSE) -> #REF!
A61: 60 | B61: Prashid Shanker | C61: 2023583466 | D61: 2301017012 | E61: B-Tech CSE-VI A | F61: =VLOOKUP('2501_MIS '!C61,'[1]Fast Track '!B:K,10,FALSE) -> #N/A | G61: =VLOOKUP(C61,[2]Sheet7!A:D,4,FALSE) -> Promoted | H61: G2 | I61: Dr. Himanshu Sharma | J61: 2023583466.prashid@ug.sharda.ac.in | K61: =VLOOKUP(C61,[3]Sheet1!D:J,6,FALSE) -> 2023583466.prakash@pt.sharda.ac.in | L61: =VLOOKUP(D61,[3]Sheet1!E:K,6,FALSE) -> 7479301653 | M61: Computer Science | O61: =VLOOKUP(C61,#REF!,12,FALSE) -> #REF!
A62: 61 | B62: Sudiksha Bhogal | C62: 2023524672 | D62: 2301017018 | E62: B-Tech CSE-VI A | F62: =VLOOKUP('2501_MIS '!C62,'[1]Fast Track '!B:K,10,FALSE) -> #N/A | G62: =VLOOKUP(C62,[2]Sheet7!A:D,4,FALSE) -> Promoted | H62: G2 | I62: Dr. Himanshu Sharma | J62: 2023524672.sudiksha@ug.sharda.ac.in | K62: =VLOOKUP(C62,[3]Sheet1!D:J,6,FALSE) -> 2023524672.sunil@pt.sharda.ac.in | L62: =VLOOKUP(D62,[3]Sheet1!E:K,6,FALSE) -> 8368285187 | M62: Computer Science | O62: =VLOOKUP(C62,#REF!,12,FALSE) -> #REF!
A63: 62 | B63: Tauhid Hashmi | C63: 2023500162 | D63: 2301017020 | E63: B-Tech CSE-VI A | F63: =VLOOKUP('2501_MIS '!C63,'[1]Fast Track '!B:K,10,FALSE) -> #N/A | G63: =VLOOKUP(C63,[2]Sheet7!A:D,4,FALSE) -> Promoted | H63: G2 | I63: Dr. Himanshu Sharma | J63: 2023500162.tauhid@ug.sharda.ac.in | K63: =VLOOKUP(C63,[3]Sheet1!D:J,6,FALSE) -> 2023500162.roshan@pt.sharda.ac.in | L63: =VLOOKUP(D63,[3]Sheet1!E:K,6,FALSE) -> 9305783117 | M63: Computer Science | O63: =VLOOKUP(C63,#REF!,12,FALSE) -> #REF!
A64: 63 | B64: Abhishek Chaudhary | C64: 2021479763 | D64: 210101025 | E64: B-Tech CSE-VI A | F64: =VLOOKUP('2501_MIS '!C64,'[1]Fast Track '!B:K,10,FALSE) -> #N/A | G64: =VLOOKUP(C64,[2]Sheet7!A:D,4,FALSE) -> Not Promoted | H64: G2 | I64: Dr. Himanshu Sharma | J64: 2021479763.abhishek@ug.sharda.ac.in | K64: 2021479763.virendra@pt.sharda.ac.in | L64: 9140907009 | M64: Computer Science | O64: =VLOOKUP(C64,#REF!,12,FALSE) -> #REF!
A65: 64 | B65: Ankit kumar | C65: 2024389953 | E65: B-Tech CSE-VI A | F65: =VLOOKUP('2501_MIS '!C65,'[1]Fast Track '!B:K,10,FALSE) -> #N/A | G65: =VLOOKUP(C65,[2]Sheet7!A:D,4,FALSE) -> Not Promoted | H65: G2 | I65: Dr. Himanshu Sharma | J65: 0 | K65: 0 | L65: 9693101494 | M65: Computer Science | O65: =VLOOKUP(C65,#REF!,12,FALSE) -> #REF!
A66: 65 | B66: Tarun Patel | C66: 2019005675 | D66: 190101319 | E66: B-Tech CSE-VI B | F66: =VLOOKUP('2501_MIS '!C66,'[1]Fast Track '!B:K,10,FALSE) -> #N/A | G66: =VLOOKUP(C66,[2]Sheet7!A:D,4,FALSE) -> Not Promoted | H66: G1 | I66: Prof. (Dr.) Jayant Shekhar | J66: 2019005675.tarun@ug.sharda.ac.in | K66: =VLOOKUP(C66,[3]Sheet1!D:J,6,FALSE) -> 0 | L66: =VLOOKUP(D66,[3]Sheet1!E:K,6,FALSE) -> 0 | M66: Computer Science | O66: =VLOOKUP(C66,#REF!,12,FALSE) -> #REF!
A67: 66 | B67: Mohammad Aatif Quamre | C67: 2020516582 | D67: 200101181 | E67: B-Tech CSE-VI B | F67: =VLOOKUP('2501_MIS '!C67,'[1]Fast Track '!B:K,10,FALSE) -> #N/A | G67: =VLOOKUP(C67,[2]Sheet7!A:D,4,FALSE) -> Not Promoted | H67: G1 | I67: Prof. (Dr.) Jayant Shekhar | K67: =VLOOKUP(C67,[3]Sheet1!D:J,6,FALSE) -> 0 | L67: =VLOOKUP(D67,[3]Sheet1!E:K,6,FALSE) -> 9319072044 | M67: Computer Science | O67: =VLOOKUP(C67,#REF!,12,FALSE) -> #REF!
A68: 67 | B68: Aditi Tiwari | C68: 2021378869 | D68: 210101036 | E68: B-Tech CSE-VI B | F68: =VLOOKUP('2501_MIS '!C68,'[1]Fast Track '!B:K,10,FALSE) -> #N/A | G68: =VLOOKUP(C68,[2]Sheet7!A:D,4,FALSE) -> Not Promoted | H68: G1 | I68: Prof. (Dr.) Jayant Shekhar | K68: =VLOOKUP(C68,[3]Sheet1!D:J,6,FALSE) -> 2021378869.lakshmipati@pt.sharda.ac.in | L68: =VLOOKUP(D68,[3]Sheet1!E:K,6,FALSE) -> 7718237260 | M68: Computer Science | O68: =VLOOKUP(C68,#REF!,12,FALSE) -> #REF!
A69: 68 | B69: Azeem Malik | C69: 2021420120 | D69: 210101143 | E69: B-Tech CSE-VI B | F69: =VLOOKUP('2501_MIS '!C69,'[1]Fast Track '!B:K,10,FALSE) -> #N/A | G69: =VLOOKUP(C69,[2]Sheet7!A:D,4,FALSE) -> #N/A | H69: G1 | I69: Prof. (Dr.) Jayant Shekhar | J69: 2021420120.azeem@ug.sharda.ac.in | K69: =VLOOKUP(C69,[3]Sheet1!D:J,6,FALSE) -> 2021420120.shahid@pt.sharda.ac.in | L69: =VLOOKUP(D69,[3]Sheet1!E:K,6,FALSE) -> 7417337133 | M69: Computer Science | N69: Left | O69: =VLOOKUP(C69,#REF!,12,FALSE) -> #REF!
A70: 69 | B70: Rinjal Sagar | C70: 2021003785 | D70: 210101586 | E70: B-Tech CSE-VI B | F70: =VLOOKUP('2501_MIS '!C70,'[1]Fast Track '!B:K,10,FALSE) -> #N/A | G70: =VLOOKUP(C70,[2]Sheet7!A:D,4,FALSE) -> Promoted | H70: G1 | I70: Prof. (Dr.) Jayant Shekhar | J70: 2021003785.rinjal@ug.sharda.ac.in | K70: =VLOOKUP(C70,[3]Sheet1!D:J,6,FALSE) -> 2021003785.lalitkumar@pt.sharda.ac.in | L70: =VLOOKUP(D70,[3]Sheet1!E:K,6,FALSE) -> 9871907908 | M70: Computer Science | O70: =VLOOKUP(C70,#REF!,12,FALSE) -> #REF!
A71: 70 | B71: A Vishwam Rao | C71: 2022003574 | D71: 2201010001 | E71: B-Tech CSE-VI B | F71: =VLOOKUP('2501_MIS '!C71,'[1]Fast Track '!B:K,10,FALSE) -> #N/A | G71: =VLOOKUP(C71,[2]Sheet7!A:D,4,FALSE) -> Promoted | H71: G1 | I71: Prof. (Dr.) Jayant Shekhar | J71: 2022003574.a@ug.sharda.ac.in | K71: =VLOOKUP(C71,[3]Sheet1!D:J,6,FALSE) -> 2022003574.rupesh@pt.sharda.ac.in | L71: =VLOOKUP(D71,[3]Sheet1!E:K,6,FALSE) -> 9971308744 | M71: Computer Science | O71: =VLOOKUP(C71,#REF!,12,FALSE) -> #REF!
A72: 71 | B72: Abhinay Singh Rawat | C72: 2022360529 | D72: 2201010022 | E72: B-Tech CSE-VI B | F72: =VLOOKUP('2501_MIS '!C72,'[1]Fast Track '!B:K,10,FALSE) -> #N/A | G72: =VLOOKUP(C72,[2]Sheet7!A:D,4,FALSE) -> Promoted | H72: G1 | I72: Prof. (Dr.) Jayant Shekhar | J72: 2022360529.abhinay@ug.sharda.ac.in | K72: =VLOOKUP(C72,[3]Sheet1!D:J,6,FALSE) -> 2022360529.harishchandra@pt.sharda.ac.in | L72: =VLOOKUP(D72,[3]Sheet1!E:K,6,FALSE) -> 7300965989 | M72: Computer Science | O72: =VLOOKUP(C72,#REF!,12,FALSE) -> #REF!
A73: 72 | B73: Ankit Yadav | C73: 2022538932 | D73: 2201010096 | E73: B-Tech CSE-VI B | F73: =VLOOKUP('2501_MIS '!C73,'[1]Fast Track '!B:K,10,FALSE) -> #N/A | G73: =VLOOKUP(C73,[2]Sheet7!A:D,4,FALSE) -> Promoted | H73: G1 | I73: Prof. (Dr.) Jayant Shekhar | J73: 2022538932.ankit@ug.sharda.ac.in | K73: =VLOOKUP(C73,[3]Sheet1!D:J,6,FALSE) -> 2022538932.chandrej@pt.sharda.ac.in | L73: =VLOOKUP(D73,[3]Sheet1!E:K,6,FALSE) -> 9625789885 | M73: Computer Science | O73: =VLOOKUP(C73,#REF!,12,FALSE) -> #REF!
A74: 73 | B74: Anshuman Singh | C74: 2022002787 | D74: 2201010105 | E74: B-Tech CSE-VI B | F74: =VLOOKUP('2501_MIS '!C74,'[1]Fast Track '!B:K,10,FALSE) -> #N/A | G74: =VLOOKUP(C74,[2]Sheet7!A:D,4,FALSE) -> Promoted | H74: G1 | I74: Prof. (Dr.) Jayant Shekhar | J74: 2022002787.anshuman@ug.sharda.ac.in | K74: =VLOOKUP(C74,[3]Sheet1!D:J,6,FALSE) -> 2022002787.ramprakash@pt.sharda.ac.in | L74: =VLOOKUP(D74,[3]Sheet1!E:K,6,FALSE) -> 8707433483 | M74: Computer Science | O74: =VLOOKUP(C74,#REF!,12,FALSE) -> #REF!
A75: 74 | B75: Anushka Kashyap | C75: 2022005229 | D75: 2201010115 | E75: B-Tech CSE-VI B | F75: =VLOOKUP('2501_MIS '!C75,'[1]Fast Track '!B:K,10,FALSE) -> #N/A | G75: =VLOOKUP(C75,[2]Sheet7!A:D,4,FALSE) -> Promoted | H75: G1 | I75: Prof. (Dr.) Jayant Shekhar | J75: 2022005229.anushka@ug.sharda.ac.in | K75: =VLOOKUP(C75,[3]Sheet1!D:J,6,FALSE) -> 2022005229.sohanlal@pt.sharda.ac.in | L75: =VLOOKUP(D75,[3]Sheet1!E:K,6,FALSE) -> 7827845687 | M75: Computer Science | O75: =VLOOKUP(C75,#REF!,12,FALSE) -> #REF!
A76: 75 | B76: Aryan Rattan Trakroo | C76: 2022419571 | D76: 2201010146 | E76: B-Tech CSE-VI B | F76: =VLOOKUP('2501_MIS '!C76,'[1]Fast Track '!B:K,10,FALSE) -> #N/A | G76: =VLOOKUP(C76,[2]Sheet7!A:D,4,FALSE) -> Promoted | H76: G2 | I76: Dr. Subrata Sahana | J76: 2022419571.aryan@ug.sharda.ac.in | K76: =VLOOKUP(C76,[3]Sheet1!D:J,6,FALSE) -> 2022419571.sanjaybharat@pt.sharda.ac.in | L76: =VLOOKUP(D76,[3]Sheet1!E:K,6,FALSE) -> 9779994998 | M76: Computer Science | O76: =VLOOKUP(C76,#REF!,12,FALSE) -> #REF!
A77: 76 | B77: Bolla Manoj Sai | C77: 2022433389 | D77: 2201010183 | E77: B-Tech CSE-VI B | F77: =VLOOKUP('2501_MIS '!C77,'[1]Fast Track '!B:K,10,FALSE) -> #N/A | G77: =VLOOKUP(C77,[2]Sheet7!A:D,4,FALSE) -> Promoted | H77: G1 | I77: Prof. (Dr.) Jayant Shekhar | J77: 2022433389.bolla@ug.sharda.ac.in | K77: =VLOOKUP(C77,[3]Sheet1!D:J,6,FALSE) -> 2022433389.bollanvssambasiva@pt.sharda.ac.in | L77: =VLOOKUP(D77,[3]Sheet1!E:K,6,FALSE) -> 9492465566 | M77: Computer Science | O77: =VLOOKUP(C77,#REF!,12,FALSE) -> #REF!
A78: 77 | B78: Brahmtej Mohanty | C78: 2022002578 | D78: 2201010184 | E78: B-Tech CSE-VI B | F78: =VLOOKUP('2501_MIS '!C78,'[1]Fast Track '!B:K,10,FALSE) -> #N/A | G78: =VLOOKUP(C78,[2]Sheet7!A:D,4,FALSE) -> Promoted | H78: G1 | I78: Prof. (Dr.) Jayant Shekhar | J78: 2022002578.brahmtej@ug.sharda.ac.in | K78: =VLOOKUP(C78,[3]Sheet1!D:J,6,FALSE) -> 2022002578.bibhutibhushan@pt.sharda.ac.in | L78: =VLOOKUP(D78,[3]Sheet1!E:K,6,FALSE) -> 7735324362 | M78: Computer Science | O78: =VLOOKUP(C78,#REF!,12,FALSE) -> #REF!
A79: 78 | B79: Chirag Pathak | C79: 2022005228 | D79: 2201010194 | E79: B-Tech CSE-VI B | F79: =VLOOKUP('2501_MIS '!C79,'[1]Fast Track '!B:K,10,FALSE) -> #N/A | G79: =VLOOKUP(C79,[2]Sheet7!A:D,4,FALSE) -> Promoted | H79: G1 | I79: Prof. (Dr.) Jayant Shekhar | J79: 2022005228.chirag@ug.sharda.ac.in | K79: =VLOOKUP(C79,[3]Sheet1!D:J,6,FALSE) -> 2022005228.sampurnanand@pt.sharda.ac.in | L79: =VLOOKUP(D79,[3]Sheet1!E:K,6,FALSE) -> 9267929004 | M79: Computer Science | O79: =VLOOKUP(C79,#REF!,12,FALSE) -> #REF!
A80: 79 | B80: Danish Kamal | C80: 2022349970 | D80: 2201010201 | E80: B-Tech CSE-VI B | F80: =VLOOKUP('2501_MIS '!C80,'[1]Fast Track '!B:K,10,FALSE) -> #N/A | G80: =VLOOKUP(C80,[2]Sheet7!A:D,4,FALSE) -> Promoted | H80: G1 | I80: Prof. (Dr.) Jayant Shekhar | J80: 2022349970.danish@ug.sharda.ac.in | K80: =VLOOKUP(C80,[3]Sheet1!D:J,6,FALSE) -> 2022349970.manzoor@pt.sharda.ac.in | L80: =VLOOKUP(D80,[3]Sheet1!E:K,6,FALSE) -> 9873222919 | M80: Computer Science | O80: =VLOOKUP(C80,#REF!,12,FALSE) -> #REF!
A81: 80 | B81: Hameem Yaseen | C81: 2022565603 | D81: 2201010257 | E81: B-Tech CSE-VI B | F81: =VLOOKUP('2501_MIS '!C81,'[1]Fast Track '!B:K,10,FALSE) -> #N/A | G81: =VLOOKUP(C81,[2]Sheet7!A:D,4,FALSE) -> Promoted | H81: G1 | I81: Prof. (Dr.) Jayant Shekhar | J81: 2022565603.hameem@ug.sharda.ac.in | K81: =VLOOKUP(C81,[3]Sheet1!D:J,6,FALSE) -> 2022565603.mohammad@pt.sharda.ac.in | L81: =VLOOKUP(D81,[3]Sheet1!E:K,6,FALSE) -> 9906660583 | M81: Computer Science | O81: =VLOOKUP(C81,#REF!,12,FALSE) -> #REF!
... A127: 126 | B127: Avik Roy | C127: 2022836161 | D127: 2201010911 | E127: B-Tech CSE-VI B | F127: =VLOOKUP('2501_MIS '!C127,'[1]Fast Track '!B:K,10,FALSE) -> #N/A | G127: =VLOOKUP(C127,[2]Sheet7!A:D,4,FALSE) -> Promoted | H127: G2 | I127: Dr. Subrata Sahana | J127: 2022836161.avik@ug.sharda.ac.in | K127: =VLOOKUP(C127,[3]Sheet1!D:J,6,FALSE) -> 2022836161.apurba@pt.sharda.ac.in | L127: =VLOOKUP(D127,[3]Sheet1!E:K,6,FALSE) -> 91 9674775066 | M127: Computer Science | O127: =VLOOKUP(C127,#REF!,12,FALSE) -> #REF!
A128: 127 | B128: Shubh Sahu | C128: 2021361239 | D128: 210101480 | E128: B-Tech CSE-VI B | F128: =VLOOKUP('2501_MIS '!C128,'[1]Fast Track '!B:K,10,FALSE) -> #N/A | G128: =VLOOKUP(C128,[2]Sheet7!A:D,4,FALSE) -> Not Promoted | H128: G2 | I128: Dr. Subrata Sahana | J128: 2021361239.shubh@ug.sharda.ac.in | K128: =VLOOKUP(C128,[3]Sheet1!D:J,6,FALSE) -> 2021361239.virendra@pt.sharda.ac.in | L128: =VLOOKUP(C128,[3]Sheet1!D:J,7,FALSE) -> 8299431338 | M128: Computer Science | O128: =VLOOKUP(C128,#REF!,12,FALSE) -> #REF!
A129: 128 | B129: Aradhya Mittal | C129: 2022480934 | D129: 2201010119 | E129: B-Tech CSE-VI C | F129: =VLOOKUP('2501_MIS '!C129,'[1]Fast Track '!B:K,10,FALSE) -> #N/A | G129: =VLOOKUP(C129,[2]Sheet7!A:D,4,FALSE) -> Promoted | H129: G1 | I129: Dr. Bal Krishna Saraswat | J129: 2022480934.aradhya@ug.sharda.ac.in | K129: =VLOOKUP(C129,[3]Sheet1!D:J,6,FALSE) -> 2022480934.sanjivkumar@pt.sharda.ac.in | L129: =VLOOKUP(D129,[3]Sheet1!E:K,6,FALSE) -> 9412810713 | M129: Computer Science | O129: =VLOOKUP(C129,#REF!,12,FALSE) -> #REF!
A130: 129 | B130: Hemant Kumar | C130: 2022441875 | D130: 2201010284 | E130: B-Tech CSE-VI C | F130: =VLOOKUP('2501_MIS '!C130,'[1]Fast Track '!B:K,10,FALSE) -> #N/A | G130: =VLOOKUP(C130,[2]Sheet7!A:D,4,FALSE) -> Promoted | H130: G1 | I130: Dr. Bal Krishna Saraswat | J130: 2022441875.hemant@ug.sharda.ac.in | K130: =VLOOKUP(C130,[3]Sheet1!D:J,6,FALSE) -> 2022441875.rajesh@pt.sharda.ac.in | L130: =VLOOKUP(D130,[3]Sheet1!E:K,6,FALSE) -> 8766227298 | M130: Computer Science | O130: =VLOOKUP(C130,#REF!,12,FALSE) -> #REF!
...

Sheet Sheet1
A1: Batch Name | B1: Sl No. | C1: Student Name | D1: Student System ID | E1: Student Roll No. | F1: New Section | G1: Program Name | H1: Student Email ID | I1: Parent mail id | J1: contact number | K1: Specialization | L1: Job Role Interest-1 | M1: Job Role Interest-2 | N1: Interested for Job(Yes/No) | S1: PE3 | T1: PE4 | U1: PE5
A2: DSAIML-L1 | B2: 2402 | C2: Anutosh Mishra | D2: 2021308861 | E2: 210101102 | F2: B-Tech CSE-VI A | G2: Bachelor of Technology | H2: 2021308861.anutosh@ug.sharda.ac.in | I2: 2021308861.ashutoshkumar@pt.sharda.ac.in | J2: 9936777552 | K2: Computer Science | L2: Machine Learning Engineer | M2: Full Stack Developer(Spring Boot) | N2: YES | O2: CSE353 | R2: HMM305 | S2: PE3 | T2: PE4 | U2: PE5 | V2: VAT013 | W2: OE-3 | X2: ARP306 | Y2: CSP353 | Z2: CSP396 | AA2: CSP390
A3: DSAIML-L1 | B3: 2402 | C3: Garv Sharma | D3: 2021529806 | E3: 210101190 | F3: B-Tech CSE-VI A | G3: Bachelor of Technology | H3: 2021529806.garv@ug.sharda.ac.in | I3: 2021529806.santosh@pt.sharda.ac.in | J3: 9711552459 | K3: Computer Science | L3: Software Developer | M3: Machine Learning Engineer | N3: YES | O3: CSE353 | R3: HMM305 | S3: PE3 | T3: PE4 | U3: PE5 | V3: VAT013 | W3: OE-3 | X3: ARP306 | Y3: CSP353 | Z3: CSP396 | AA3: CSP390
A4: DSAIML-L1 | B4: 2402 | C4: Nandani Chaudhary | D4: 2021828405 | E4: 210101591 | F4: B-Tech CSE-VI A | G4: Bachelor of Technology | H4: 2021828405.nandani@ug.sharda.ac.in | I4: 2021828405.ramananda@pt.sharda.ac.in | J4: 8130538380 | K4: Computer Science | L4: Data Scientist | M4: Cyber Security Analyst | N4: YES | O4: CSE353 | R4: HMM305 | S4: PE3 | T4: PE4 | U4: PE5 | V4: VAT013 | W4: OE-3 | X4: ARP306 | Y4: CSP353 | Z4: CSP396 | AA4: CSP390
A5: DSAIML-L1 | B5: 2402 | C5: Farheen Khan | D5: 2021000009 | E5: 210121021 | F5: B-Tech CSE-VI A | G5: Bachelor of Technology | H5: 2021000009.farheen@ug.sharda.ac.in | I5: 2021000009.asad@pt.sharda.ac.in | J5: 9599543010 | K5: Computer Science | L5: Software Developer | M5: Cyber Security Analyst | N5: YES | O5: CSE353 | R5: HMM305 | S5: PE3 | T5: PE4 | U5: PE5 | V5: VAT013 | W5: OE-3 | X5: ARP306 | Y5: CSP353 | Z5: CSP396 | AA5: CSP390
A6: DSAIML-L1 | B6: 2402 | C6: Abhiraj Singh | D6: 2022579515 | E6: 2201010023 | F6: B-Tech CSE-VI A | G6: Bachelor of Technology | H6: 2022579515.abhiraj@ug.sharda.ac.in | I6: 2022579515.vijaykumar@pt.sharda.ac.in | J6: 8826793887 | K6: Computer Science | L6: Data Scientist | M6: Machine Learning Engineer | N6: YES | O6: CSE353 | R6: HMM305 | S6: PE3 | T6: PE4 | U6: PE5 | V6: VAT013 | W6: OE-3 | X6: ARP306 | Y6: CSP353 | Z6: CSP396 | AA6: CSP390
A7: DSAIML-L1 | B7: 2402 | C7: Aman Sinha | D7: 2022534811 | E7: 2201010078 | F7: B-Tech CSE-VI A | G7: Bachelor of Technology | H7: 2022534811.aman@ug.sharda.ac.in | I7: 2022534811.rajeshkumar@pt.sharda.ac.in | J7: 7319641049 | K7: Computer Science | L7: Software Developer | M7: Data Scientist | N7: NO | O7: CSE353 | R7: HMM305 | S7: PE3 | T7: PE4 | U7: PE5 | V7: VAT013 | W7: OE-3 | X7: ARP306 | Y7: CSP353 | Z7: CSP396 | AA7: CSP390
A8: DSAIML-L1 | B8: 2402 | C8: Ansh Shrivastav | D8: 2022475156 | E8: 2201010099 | F8: B-Tech CSE-VI A | G8: Bachelor of Technology | H8: 2022475156.ansh@ug.sharda.ac.in | I8: 2022475156.dhananjay@pt.sharda.ac.in | J8: 8789919805 | K8: Computer Science | L8: Machine Learning Engineer | M8: Machine Learning Engineer | N8: YES | O8: CSE353 | R8: HMM305 | S8: PE3 | T8: PE4 | U8: PE5 | V8: VAT013 | W8: OE-3 | X8: ARP306 | Y8: CSP353 | Z8: CSP396 | AA8: CSP390
A9: DSAIML-L1 | B9: 2402 | C9: Anuj Rawat | D9: 2022394343 | E9: 2201010111 | F9: B-Tech CSE-VI A | G9: Bachelor of Technology | H9: 2022394343.anuj@ug.sharda.ac.in | I9: 2022394343.anandsingh@pt.sharda.ac.in | J9: 8126133363 | K9: Computer Science | L9: Data Scientist | M9: Software Developer | N9: YES | O9: CSE353 | R9: HMM305 | S9: PE3 | T9: PE4 | U9: PE5 | V9: VAT013 | W9: OE-3 | X9: ARP306 | Y9: CSP353 | Z9: CSP396 | AA9: CSP390
A10: DSAIML-L1 | B10: 2402 | C10: Arbaz Ahmed | D10: 2022006308 | E10: 2201010121 | F10: B-Tech CSE-VI A | G10: Bachelor of Technology | H10: 2022006308.arbaz@ug.sharda.ac.in | I10: 2022006308.asad@pt.sharda.ac.in | J10: 7300577335 | K10: Computer Science | L10: Software Developer | M10: Machine Learning Engineer | N10: YES | O10: CSE353 | R10: HMM305 | S10: PE3 | T10: PE4 | U10: PE5 | V10: VAT013 | W10: OE-3 | X10: ARP306 | Y10: CSP353 | Z10: CSP396 | AA10: CSP390
A11: DSAIML-L1 | B11: 2402 | C11: Atithi Negi | D11: 2022438604 | E11: 2201010162 | F11: B-Tech CSE-VI A | G11: Bachelor of Technology | H11: 2022438604.atithi@ug.sharda.ac.in | I11: 2022438604.kundansingh@pt.sharda.ac.in | J11: 8920297350 | K11: Computer Science | L11: Software Developer | M11: Data Scientist | N11: YES | O11: CSE353 | R11: HMM305 | S11: PE3 | T11: PE4 | U11: PE5 | V11: VAT013 | W11: OE-3 | X11: ARP306 | Y11: CSP353 | Z11: CSP396 | AA11: CSP390
A12: DSAIML-L1 | B12: 2402 | C12: Basharat Hassan | D12: 2022521926 | E12: 2201010175 | F12: B-Tech CSE-VI A | G12: Bachelor of Technology | H12: 2022521926.basharat@ug.sharda.ac.in | I12: 2022521926.ghulamhassan@pt.sharda.ac.in | J12: 8899544845 | K12: Computer Science | L12: Machine Learning Engineer | M12: Cyber Security Analyst | N12: NO | O12: CSE353 | R12: HMM305 | S12: PE3 | T12: PE4 | U12: PE5 | V12: VAT013 | W12: OE-3 | X12: ARP306 | Y12: CSP353 | Z12: CSP396 | AA12: CSP390
A13: DSAIML-L1 | B13: 2402 | C13: Bhoomi Sharma | D13: 2022325232 | E13: 2201010178 | F13: B-Tech CSE-VI A | G13: Bachelor of Technology | H13: 2022325232.bhoomi@ug.sharda.ac.in | I13: 2022325232.latesuneet@pt.sharda.ac.in | J13: 9717628588 | K13: Computer Science | L13: Data Scientist | M13: Cloud Engineer | N13: YES | O13: CSE353 | R13: HMM305 | S13: PE3 | T13: PE4 | U13: PE5 | V13: VAT013 | W13: OE-3 | X13: ARP306 | Y13: CSP353 | Z13: CSP396 | AA13: CSP390
... A27: DSAIML-L1 | B27: 2402 | C27: Rakshit Garg | D27: 2022563106 | E27: 2201010558 | F27: B-Tech CSE-VI A | G27: Bachelor of Technology | H27: 2022563106.rakshit@ug.sharda.ac.in | I27: 2022563106.sanjaykumar@pt.sharda.ac.in | J27: 8929565652 | K27: Computer Science | L27: Machine Learning Engineer | M27: Cyber Security Analyst | N27: YES | O27: CSE353 | R27: HMM305 | S27: PE3 | T27: PE4 | U27: PE5 | V27: VAT013 | W27: OE-3 | X27: ARP306 | Y27: CSP353 | Z27: CSP396 | AA27: CSP390
A28: DSAIML-L1 | B28: 2402 | C28: Rohan Srivastava | D28: 2022506102 | E28: 2201010597 | F28: B-Tech CSE-VI A | G28: Bachelor of Technology | H28: 2022506102.rohan@ug.sharda.ac.in | I28: 2022506102.santoshkumar@pt.sharda.ac.in | J28: 8887501600 | K28: Computer Science | L28: #N/A | M28: #N/A | N28: #N/A | O28: CSE353 | R28: HMM305 | S28: PE3 | T28: PE4 | U28: PE5 | V28: VAT013 | W28: OE-3 | X28: ARP306 | Y28: CSP353 | Z28: CSP396 | AA28: CSP390
A29: DSAIML-L1 | B29: 2402 | C29: Rudra Pratap Tomar | D29: 2022478036 | E29: 2201010605 | F29: B-Tech CSE-VI A | G29: Bachelor of Technology | H29: 2022478036.rudra@ug.sharda.ac.in | I29: 2022478036.ajay@pt.sharda.ac.in | J29: 9358584820 | K29: Computer Science | L29: Software Developer | M29: Full Stack Developer(Spring Boot) | N29: YES | O29: CSE353 | R29: HMM305 | S29: PE3 | T29: PE4 | U29: PE5 | V29: VAT013 | W29: OE-3 | X29: ARP306 | Y29: CSP353 | Z29: CSP396 | AA29: CSP390
A30: DSAIML-L1 | B30: 2402 | C30: Sanket Sharma | D30: 2022344264 | E30: 2201010634 | F30: B-Tech CSE-VI A | G30: Bachelor of Technology | H30: 2022344264.sanket@ug.sharda.ac.in | I30: 2022344264.krishna@pt.sharda.ac.in | J30: 9899045081 | K30: Computer Science | L30: Software Developer | M30: Cyber Security Analyst | N30: YES | O30: CSE353 | R30: HMM305 | S30: PE3 | T30: PE4 | U30: PE5 | V30: VAT013 | W30: OE-3 | X30: ARP306 | Y30: CSP353 | Z30: CSP396 | AA30: CSP390
A31: DSAIML-L1 | B31: 2402 | C31: Sanskriti Verma | D31: 2022004547 | E31: 2201010635 | F31: B-Tech CSE-VI A | G31: Bachelor of Technology | H31: 2022004547.sanskriti@ug.sharda.ac.in | I31: 2022004547.sanjay@pt.sharda.ac.in | J31: 7011428007 | K31: Computer Science | L31: Machine Learning Engineer | M31: Software Developer | N31: YES | O31: CSE353 | R31: HMM305 | S31: PE3 | T31: PE4 | U31: PE5 | V31: VAT013 | W31: OE-3 | X31: ARP306 | Y31: CSP353 | Z31: CSP396 | AA31: CSP390
A32: DSAIML-L1 | B32: 2402 | C32: Saumya Suman | D32: 2022438521 | E32: 2201010646 | F32: B-Tech CSE-VI A | G32: Bachelor of Technology | H32: 2022438521.saumya@ug.sharda.ac.in | I32: 2022438521.lateshankar@pt.sharda.ac.in | J32: 7979996286 | K32: Computer Science | L32: Software Developer | M32: Data Scientist | N32: YES | O32: CSE353 | R32: HMM305 | S32: PE3 | T32: PE4 | U32: PE5 | V32: VAT013 | W32: OE-3 | X32: ARP306 | Y32: CSP353 | Z32: CSP396 | AA32: CSP390
A33: DSAIML-L1 | B33: 2402 | C33: Shaurya Singh | D33: 2022006789 | E33: 2201010661 | F33: B-Tech CSE-VI A | G33: Bachelor of Technology | H33: 2022006789.shaurya@ug.sharda.ac.in | I33: 2022006789.kishan@pt.sharda.ac.in | J33: 8750854190 | K33: Computer Science | L33: Machine Learning Engineer | M33: Android Developer | N33: YES | O33: CSE353 | R33: HMM305 | S33: PE3 | T33: PE4 | U33: PE5 | V33: VAT013 | W33: OE-3 | X33: ARP306 | Y33: CSP353 | Z33: CSP396 | AA33: CSP390
A34: DSAIML-L1 | B34: 2402 | C34: Shivam Kaintyura | D34: 2022472720 | E34: 2201010668 | F34: B-Tech CSE-VI A | G34: Bachelor of Technology | H34: 2022472720.shivam@ug.sharda.ac.in | I34: 2022472720.brijmohan@pt.sharda.ac.in | J34: 9458354480 | K34: Computer Science | L34: Full Stack Developer(Spring Boot) | M34: Software Developer | N34: YES | O34: CSE353 | R34: HMM305 | S34: PE3 | T34: PE4 | U34: PE5 | V34: VAT013 | W34: OE-3 | X34: ARP306 | Y34: CSP353 | Z34: CSP396 | AA34: CSP390
A35: DSAIML-L1 | B35: 2402 | C35: Shivam Kumar | D35: 2022577110 | E35: 2201010671 | F35: B-Tech CSE-VI A | G35: Bachelor of Technology | H35: 2022577110.shivam@ug.sharda.ac.in | I35: 2022577110.udayshankar@pt.sharda.ac.in | J35: 9508885660 | K35: Computer Science | L35: Software Developer | M35: Machine Learning Engineer | N35: YES | O35: CSE353 | R35: HMM305 | S35: PE3 | T35: PE4 | U35: PE5 | V35: VAT013 | W35: OE-3 | X35: ARP306 | Y35: CSP353 | Z35: CSP396 | AA35: CSP390
A36: DSAIML-L1 | B36: 2402 | C36: Shivam Yadav | D36: 2022432518 | E36: 2201010676 | F36: B-Tech CSE-VI A | G36: Bachelor of Technology | H36: 2022432518.shivam@ug.sharda.ac.in | I36: 2022432518.pramodkumar@pt.sharda.ac.in | J36: 7983413394 | K36: Computer Science | L36: Software Developer | M36: Full Stack Developer(Spring Boot) | N36: YES | O36: CSE353 | R36: HMM305 | S36: PE3 | T36: PE4 | U36: PE5 | V36: VAT013 | W36: OE-3 | X36: ARP306 | Y36: CSP353 | Z36: CSP396 | AA36: CSP390
A37: DSAIML-L1 | B37: 2402 | C37: Shobhit Agrawal | D37: 2022512360 | E37: 2201010681 | F37: B-Tech CSE-VI A | G37: Bachelor of Technology | H37: 2022512360.shobhit@ug.sharda.ac.in | I37: 2022512360.ramprasad@pt.sharda.ac.in | J37: 7651937775 | K37: Computer Science | L37: Data Scientist | M37: Software Developer | N37: YES | O37: CSE353 | R37: HMM305 | S37: PE3 | T37: PE4 | U37: PE5 | V37: VAT013 | W37: OE-3 | X37: ARP306 | Y37: CSP353 | Z37: CSP396 | AA37: CSP390
A38: DSAIML-L1 | B38: 2402 | C38: Shreyal Gupta | D38: 2022004756 | E38: 2201010684 | F38: B-Tech CSE-VI A | G38: Bachelor of Technology | H38: 2022004756.shreyal@ug.sharda.ac.in | I38: 2022004756.manish@pt.sharda.ac.in | J38: 8439840461 | K38: Computer Science | L38: Software Developer | M38: Full Stack Developer(Spring Boot) | N38: YES | O38: CSE353 | R38: HMM305 | S38: PE3 | T38: PE4 | U38: PE5 | V38: VAT013 | W38: OE-3 | X38: ARP306 | Y38: CSP353 | Z38: CSP396 | AA38: CSP390
A39: DSAIML-L1 | B39: 2402 | C39: Shubhojit Sen | D39: 2022520978 | E39: 2201010693 | F39: B-Tech CSE-VI A | G39: Bachelor of Technology | H39: 2022520978.shubhojit@ug.sharda.ac.in | I39: 2022520978.abhijit@pt.sharda.ac.in | J39: 7080050607 | K39: Computer Science | L39: Software Developer | M39: Machine Learning Engineer | N39: YES | O39: CSE353 | R39: HMM305 | S39: PE3 | T39: PE4 | U39: PE5 | V39: VAT013 | W39: OE-3 | X39: ARP306 | Y39: CSP353 | Z39: CSP396 | AA39: CSP390
A40: DSAIML-L1 | B40: 2402 | C40: Suhail Nazir Taili | D40: 2022003913 | E40: 2201010718 | F40: B-Tech CSE-VI A | G40: Bachelor of Technology | H40: 2022003913.suhail@ug.sharda.ac.in | I40: 2022003913.nazirahmad@pt.sharda.ac.in | J40: 7006837134 | K40: Computer Science | L40: Cloud Engineer | M40: Data Scientist | N40: YES | O40: CSE353 | R40: HMM305 | S40: PE3 | T40: PE4 | U40: PE5 | V40: VAT013 | W40: OE-3 | X40: ARP306 | Y40: CSP353 | Z40: CSP396 | AA40: CSP390
... A63: DSAIML-L1 | B63: 2402 | C63: Tauhid Hashmi | D63: 2023500162 | E63: 2301017020 | F63: B-Tech CSE-VI A | G63: Bachelor of Technology | H63: 2023500162.tauhid@ug.sharda.ac.in | I63: 2023500162.roshan@pt.sharda.ac.in | J63: 9305783117 | K63: Computer Science | L63: Full Stack Developer(MERN Stack) | M63: Android Developer | N63: YES | O63: CSE353 | R63: HMM305 | S63: PE3 | T63: PE4 | U63: PE5 | V63: VAT013 | W63: OE-3 | X63: ARP306 | Y63: CSP353 | Z63: CSP396 | AA63: CSP390
A64: DSAIML-L1 | B64: 2402 | C64: Abhishek Chaudhary | D64: 2021479763 | E64: 210101025 | F64: B-Tech CSE-VI A | G64: Bachelor of Technology | H64: 2021479763.abhishek@ug.sharda.ac.in | I64: 2021479763.virendra@pt.sharda.ac.in | J64: 9140907009 | K64: Computer Science | O64: CSE353 | R64: HMM305 | S64: PE3 | T64: PE4 | U64: PE5 | V64: VAT013 | W64: OE-3 | X64: ARP306 | Y64: CSP353 | Z64: CSP396 | AA64: CSP390
A65: DSAIML-L1 | B65: 2402 | C65: Ankit kumar | D65: 2024389953 | F65: B-Tech CSE-VI A | G65: Bachelor of Technology | H65: 0 | I65: 0 | J65: 9693101494 | K65: Computer Science | O65: CSE353 | R65: HMM305 | S65: PE3 | T65: PE4 | U65: PE5 | V65: VAT013 | W65: OE-3 | X65: ARP306 | Y65: CSP353 | Z65: CSP396 | AA65: CSP390
A66: Cyber Security-L1 | B66: 2402 | C66: Tarun Patel | D66: 2019005675 | E66: 190101319 | F66: B-Tech CSE-VI B | G66: Bachelor of Technology | I66: 0 | J66: 0 | K66: Computer Science | O66: CSE353 | R66: HMM305 | S66: PE3 | T66: PE4 | U66: PE5 | V66: VAT013 | W66: OE-3 | X66: ARP306 | Y66: CSP353 | Z66: CSP396 | AA66: CSP390
A67: Cyber Security-L1 | B67: 2402 | C67: Mohammad Aatif Quamre | D67: 2020516582 | E67: 200101181 | F67: B-Tech CSE-VI B | G67: Bachelor of Technology | I67: 0 | J67: 9319072044 | K67: Computer Science | O67: CSE353 | R67: HMM305 | S67: PE3 | T67: PE4 | U67: PE5 | V67: VAT013 | W67: OE-3 | X67: ARP306 | Y67: CSP353 | Z67: CSP396 | AA67: CSP390
A68: Cyber Security-L1 | B68: 2402 | C68: Aditi Tiwari | D68: 2021378869 | E68: 210101036 | F68: B-Tech CSE-VI B | G68: Bachelor of Technology | I68: 2021378869.lakshmipati@pt.sharda.ac.in | J68: 7718237260 | K68: Computer Science | O68: CSE353 | R68: HMM305 | S68: PE3 | T68: PE4 | U68: PE5 | V68: VAT013 | W68: OE-3 | X68: ARP306 | Y68: CSP353 | Z68: CSP396 | AA68: CSP390
A69: Cyber Security-L1 | B69: 2402 | C69: Azeem Malik | D69: 2021420120 | E69: 210101143 | F69: B-Tech CSE-VI B | G69: Bachelor of Technology | H69: 2021420120.azeem@ug.sharda.ac.in | I69: 2021420120.shahid@pt.sharda.ac.in | J69: 7417337133 | K69: Computer Science | L69: #N/A | M69: #N/A | N69: #N/A | O69: CSE353 | R69: HMM305 | S69: PE3 | T69: PE4 | U69: PE5 | V69: VAT013 | W69: OE-3 | X69: ARP306 | Y69: CSP353 | Z69: CSP396 | AA69: CSP390
A70: Cyber Security-L1 | B70: 2402 | C70: Rinjal Sagar | D70: 2021003785 | E70: 210101586 | F70: B-Tech CSE-VI B | G70: Bachelor of Technology | H70: 2021003785.rinjal@ug.sharda.ac.in | I70: 2021003785.lalitkumar@pt.sharda.ac.in | J70: 9871907908 | K70: Computer Science | L70: #N/A | M70: #N/A | N70: #N/A | O70: CSE353 | R70: HMM305 | S70: PE3 | T70: PE4 | U70: PE5 | V70: VAT013 | W70: OE-3 | X70: ARP306 | Y70: CSP353 | Z70: CSP396 | AA70: CSP390
A71: Cyber Security-L1 | B71: 2402 | C71: A Vishwam Rao | D71: 2022003574 | E71: 2201010001 | F71: B-Tech CSE-VI B | G71: Bachelor of Technology | H71: 2022003574.a@ug.sharda.ac.in | I71: 2022003574.rupesh@pt.sharda.ac.in | J71: 9971308744 | K71: Computer Science | L71: Software Developer | M71: Software Developer | N71: YES | O71: CSE353 | R71: HMM305 | S71: PE3 | T71: PE4 | U71: PE5 | V71: VAT013 | W71: OE-3 | X71: ARP306 | Y71: CSP353 | Z71: CSP396 | AA71: CSP390
A72: Cyber Security-L1 | B72: 2402 | C72: Abhinay Singh Rawat | D72: 2022360529 | E72: 2201010022 | F72: B-Tech CSE-VI B | G72: Bachelor of Technology | H72: 2022360529.abhinay@ug.sharda.ac.in | I72: 2022360529.harishchandra@pt.sharda.ac.in | J72: 7300965989 | K72: Computer Science | L72: Cyber Security Analyst | M72: Android Developer | N72: YES | O72: CSE353 | R72: HMM305 | S72: PE3 | T72: PE4 | U72: PE5 | V72: VAT013 | W72: OE-3 | X72: ARP306 | Y72: CSP353 | Z72: CSP396 | AA72: CSP390
A73: Cyber Security-L1 | B73: 2402 | C73: Ankit Yadav | D73: 2022538932 | E73: 2201010096 | F73: B-Tech CSE-VI B | G73: Bachelor of Technology | H73: 2022538932.ankit@ug.sharda.ac.in | I73: 2022538932.chandrej@pt.sharda.ac.in | J73: 9625789885 | K73: Computer Science | L73: Cyber Security Analyst | M73: Data Scientist | N73: NO | O73: CSE353 | R73: HMM305 | S73: PE3 | T73: PE4 | U73: PE5 | V73: VAT013 | W73: OE-3 | X73: ARP306 | Y73: CSP353 | Z73: CSP396 | AA73: CSP390
A74: Cyber Security-L1 | B74: 2402 | C74: Anshuman Singh | D74: 2022002787 | E74: 2201010105 | F74: B-Tech CSE-VI B | G74: Bachelor of Technology | H74: 2022002787.anshuman@ug.sharda.ac.in | I74: 2022002787.ramprakash@pt.sharda.ac.in | J74: 8707433483 | K74: Computer Science | L74: Software Developer | M74: Full Stack Developer(MERN Stack) | N74: NO | O74: CSE353 | R74: HMM305 | S74: PE3 | T74: PE4 | U74: PE5 | V74: VAT013 | W74: OE-3 | X74: ARP306 | Y74: CSP353 | Z74: CSP396 | AA74: CSP390
A75: Cyber Security-L1 | B75: 2402 | C75: Anushka Kashyap | D75: 2022005229 | E75: 2201010115 | F75: B-Tech CSE-VI B | G75: Bachelor of Technology | H75: 2022005229.anushka@ug.sharda.ac.in | I75: 2022005229.sohanlal@pt.sharda.ac.in | J75: 7827845687 | K75: Computer Science | L75: Cyber Security Analyst | M75: Full Stack Developer(Spring Boot) | N75: YES | O75: CSE353 | R75: HMM305 | S75: PE3 | T75: PE4 | U75: PE5 | V75: VAT013 | W75: OE-3 | X75: ARP306 | Y75: CSP353 | Z75: CSP396 | AA75: CSP390
...

Sheet MIS
A1: Sl No. | B1: Student Name | C1: Student System ID | D1: Student Roll No. | E1: New Section | F1: Fast Track | H1: Parent mail id | I1: contact number | J1: Specialization | K1: Group | L1: Mentor
A2: 1 | B2: Anutosh Mishra | C2: 2021308861 | D2: 210101102 | E2: B-Tech CSE-VI A | F2: =VLOOKUP(C2,'Fast Track '!B:C,2,FALSE) -> #N/A | G2: Introduction to Internet of Things_CSE071 | H2: =VLOOKUP(C2,Sheet1!D:J,6,FALSE) -> 2021308861.ashutoshkumar@pt.sharda.ac.in | I2: =VLOOKUP(D2,Sheet1!E:K,6,FALSE) -> 9936777552 | J2: Computer Science | K2: G1 | L2: Ms. Aanchal Vij
A3: 2 | B3: Nandani Chaudhary | C3: 2021828405 | D3: 210101591 | E3: B-Tech CSE-VI A | F3: =VLOOKUP(C3,'Fast Track '!B:C,2,FALSE) -> #N/A | G3: Introduction to Internet of Things_CSE071 | H3: =VLOOKUP(C3,Sheet1!D:J,6,FALSE) -> 2021828405.ramananda@pt.sharda.ac.in | I3: =VLOOKUP(D3,Sheet1!E:K,6,FALSE) -> 8130538380 | J3: Computer Science | K3: G1 | L3: Ms. Aanchal Vij
A4: 3 | B4: Farheen Khan | C4: 2021000009 | D4: 210121021 | E4: B-Tech CSE-VI A | F4: =VLOOKUP(C4,'Fast Track '!B:C,2,FALSE) -> #N/A | G4: Introduction to Internet of Things_CSE071 | H4: =VLOOKUP(C4,Sheet1!D:J,6,FALSE) -> 2021000009.asad@pt.sharda.ac.in | I4: =VLOOKUP(D4,Sheet1!E:K,6,FALSE) -> 9599543010 | J4: Computer Science | K4: G1 | L4: Ms. Aanchal Vij
A5: 4 | B5: Abhiraj Singh | C5: 2022579515 | D5: 2201010023 | E5: B-Tech CSE-VI A | F5: =VLOOKUP(C5,'Fast Track '!B:C,2,FALSE) -> #N/A | G5: Introduction to Internet of Things_CSE071 | H5: =VLOOKUP(C5,Sheet1!D:J,6,FALSE) -> 2022579515.vijaykumar@pt.sharda.ac.in | I5: =VLOOKUP(D5,Sheet1!E:K,6,FALSE) -> 8826793887 | J5: Computer Science | K5: G1 | L5: Ms. Aanchal Vij
A6: 5 | B6: Aman Sinha | C6: 2022534811 | D6: 2201010078 | E6: B-Tech CSE-VI A | F6: =VLOOKUP(C6,'Fast Track '!B:C,2,FALSE) -> #N/A | G6: Introduction to Internet of Things_CSE071 | H6: =VLOOKUP(C6,Sheet1!D:J,6,FALSE) -> 2022534811.rajeshkumar@pt.sharda.ac.in | I6: =VLOOKUP(D6,Sheet1!E:K,6,FALSE) -> 7319641049 | J6: Computer Science | K6: G1 | L6: Ms. Aanchal Vij
A7: 6 | B7: Ansh Shrivastav | C7: 2022475156 | D7: 2201010099 | E7: B-Tech CSE-VI A | F7: =VLOOKUP(C7,'Fast Track '!B:C,2,FALSE) -> #N/A | G7: Introduction to Internet of Things_CSE071 | H7: =VLOOKUP(C7,Sheet1!D:J,6,FALSE) -> 2022475156.dhananjay@pt.sharda.ac.in | I7: =VLOOKUP(D7,Sheet1!E:K,6,FALSE) -> 8789919805 | J7: Computer Science | K7: G1 | L7: Ms. Aanchal Vij
A8: 7 | B8: Anuj Rawat | C8: 2022394343 | D8: 2201010111 | E8: B-Tech CSE-VI A | F8: =VLOOKUP(C8,'Fast Track '!B:C,2,FALSE) -> #N/A | G8: Introduction to Internet of Things_CSE071 | H8: =VLOOKUP(C8,Sheet1!D:J,6,FALSE) -> 2022394343.anandsingh@pt.sharda.ac.in | I8: =VLOOKUP(D8,Sheet1!E:K,6,FALSE) -> 8126133363 | J8: Computer Science | K8: G1 | L8: Ms. Aanchal Vij
A9: 8 | B9: Arbaz Ahmed | C9: 2022006308 | D9: 2201010121 | E9: B-Tech CSE-VI A | F9: =VLOOKUP(C9,'Fast Track '!B:C,2,FALSE) -> #N/A | G9: Introduction to Internet of Things_CSE071 | H9: =VLOOKUP(C9,Sheet1!D:J,6,FALSE) -> 2022006308.asad@pt.sharda.ac.in | I9: =VLOOKUP(D9,Sheet1!E:K,6,FALSE) -> 7300577335 | J9: Computer Science | K9: G1 | L9: Ms. Aanchal Vij
A10: 9 | B10: Atithi Negi | C10: 2022438604 | D10: 2201010162 | E10: B-Tech CSE-VI A | F10: =VLOOKUP(C10,'Fast Track '!B:C,2,FALSE) -> #N/A | G10: Introduction to Internet of Things_CSE071 | H10: =VLOOKUP(C10,Sheet1!D:J,6,FALSE) -> 2022438604.kundansingh@pt.sharda.ac.in | I10: =VLOOKUP(D10,Sheet1!E:K,6,FALSE) -> 8920297350 | J10: Computer Science | K10: G1 | L10: Ms. Aanchal Vij
A11: 10 | B11: Basharat Hassan | C11: 2022521926 | D11: 2201010175 | E11: B-Tech CSE-VI A | F11: =VLOOKUP(C11,'Fast Track '!B:C,2,FALSE) -> #N/A | G11: Introduction to Internet of Things_CSE071 | H11: =VLOOKUP(C11,Sheet1!D:J,6,FALSE) -> 2022521926.ghulamhassan@pt.sharda.ac.in | I11: =VLOOKUP(D11,Sheet1!E:K,6,FALSE) -> 8899544845 | J11: Computer Science | K11: G1 | L11: Ms. Aanchal Vij
A12: 11 | B12: Bhoomi Sharma | C12: 2022325232 | D12: 2201010178 | E12: B-Tech CSE-VI A | F12: =VLOOKUP(C12,'Fast Track '!B:C,2,FALSE) -> #N/A | G12: Introduction to Internet of Things_CSE071 | H12: =VLOOKUP(C12,Sheet1!D:J,6,FALSE) -> 2022325232.latesuneet@pt.sharda.ac.in | I12: =VLOOKUP(D12,Sheet1!E:K,6,FALSE) -> 9717628588 | J12: Computer Science | K12: G1 | L12: Ms. Aanchal Vij
A13: 12 | B13: Chirag Nirwan | C13: 2022305905 | D13: 2201010193 | E13: B-Tech CSE-VI A | F13: =VLOOKUP(C13,'Fast Track '!B:C,2,FALSE) -> #N/A | G13: Introduction to Internet of Things_CSE071 | H13: =VLOOKUP(C13,Sheet1!D:J,6,FALSE) -> 2022305905.sanjeev@pt.sharda.ac.in | I13: =VLOOKUP(D13,Sheet1!E:K,6,FALSE) -> 9311273352 | J13: Computer Science | K13: G1 | L13: Ms. Aanchal Vij
... A57: 56 | B57: Sudiksha Bhogal | C57: 2023524672 | D57: 2301017018 | E57: B-Tech CSE-VI A | F57: =VLOOKUP(C57,'Fast Track '!B:C,2,FALSE) -> #N/A | G57: Introduction to Internet of Things_CSE071 | H57: =VLOOKUP(C57,Sheet1!D:J,6,FALSE) -> 2023524672.sunil@pt.sharda.ac.in | I57: =VLOOKUP(D57,Sheet1!E:K,6,FALSE) -> 8368285187 | J57: Computer Science | K57: G2 | L57: Ms. Aanchal Vij
A58: 57 | B58: Abhishek Chaudhary | C58: 2021479763 | D58: 210101025 | E58: B-Tech CSE-VI A | F58: =VLOOKUP(C58,'Fast Track '!B:C,2,FALSE) -> #N/A | G58: Introduction to Internet of Things_CSE071 | H58: 2021479763.virendra@pt.sharda.ac.in | I58: 9140907009 | J58: Computer Science | K58: G2 | L58: Ms. Aanchal Vij
A59: 58 | B59: Ankit kumar | C59: 2024389953 | E59: B-Tech CSE-VI A | F59: =VLOOKUP(C59,'Fast Track '!B:C,2,FALSE) -> #N/A | G59: Introduction to Internet of Things_CSE071 | H59: 0 | I59: 9693101494 | J59: Computer Science | K59: G2 | L59: Ms. Aanchal Vij
A60: 59 | B60: Shubham Sharma | C60: 2022006289 | D60: 2201010959 | E60: B-Tech CSE-VI A | F60: =VLOOKUP(C60,'Fast Track '!B:C,2,FALSE) -> Fasttrack | H60: 2022006289.shyambir@pt.sharda.ac.in | I60: 7982036498 | J60: CSE- IOT & Application | K60: G2 | L60: Ms. Aanchal Vij
A61: 60 | B61: Nitin Chauhan | C61: 2022008160 | D61: 2201010970 | E61: B-Tech CSE-VI A | F61: =VLOOKUP(C61,'Fast Track '!B:C,2,FALSE) -> #N/A | G61: Introduction to Internet of Things_CSE071 | H61: 2022008160.shiv@pt.sharda.ac.in | I61: 7408921681 | J61: CSE- IOT & Application | K61: G2 | L61: Ms. Aanchal Vij
A62: 61 | B62: Ashutosh Kumar | C62: 2022006860 | D62: 2201010154 | E62: B-Tech CSE-VI A | F62: =VLOOKUP(C62,'Fast Track '!B:C,2,FALSE) -> #N/A | G62: Introduction to Internet of Things_CSE071 | H62: 2022006860.ravi@pt.sharda.ac.in | I62: 8877464245 | J62: CSE- IOT & Application | K62: G2 | L62: Ms. Aanchal Vij
A63: 62 | B63: Harshit . | C63: 2022489738 | D63: 2201010276 | E63: B-Tech CSE-VI A | F63: =VLOOKUP(C63,'Fast Track '!B:C,2,FALSE) -> #N/A | G63: Introduction to Internet of Things_CSE071 | H63: 2022489738.deepak@pt.sharda.ac.in | I63: 7988496098 | J63: CSE- IOT & Application | K63: G2 | L63: Ms. Aanchal Vij
A64: 63 | B64: Rachit Sinha | C64: 2022002885 | D64: 2201010957 | E64: B-Tech CSE-VI A | F64: =VLOOKUP(C64,'Fast Track '!B:C,2,FALSE) -> #N/A | G64: Introduction to Internet of Things_CSE071 | H64: 2022002885.sanjaykumar@pt.sharda.ac.in | I64: 9625967510 | J64: CSE- IOT & Application | K64: G2 | L64: Ms. Aanchal Vij
A65: 64 | B65: Dev Singh | C65: 2022004595 | D65: 2201010958 | E65: B-Tech CSE-VI A | F65: =VLOOKUP(C65,'Fast Track '!B:C,2,FALSE) -> #N/A | G65: Introduction to Internet of Things_CSE071 | H65: 2022004595.hira@pt.sharda.ac.in | I65: 8595711734 | J65: CSE- IOT & Application | K65: G2 | L65: Ms. Aanchal Vij
A66: 65 | B66: Mohammad Aatif Quamre | C66: 2020516582 | D66: 200101181 | E66: B-Tech CSE-VI B | F66: =VLOOKUP(C66,'Fast Track '!B:C,2,FALSE) -> #N/A | G66: Introduction to Internet of Things_CSE071 | I66: =VLOOKUP(D66,Sheet1!E:K,6,FALSE) -> 9319072044 | J66: Computer Science | K66: G1 | L66: Dr. Abhishek Singh Verma
A67: 66 | B67: Aditi Tiwari | C67: 2021378869 | D67: 210101036 | E67: B-Tech CSE-VI B | F67: =VLOOKUP(C67,'Fast Track '!B:C,2,FALSE) -> #N/A | G67: Introduction to Internet of Things_CSE071 | I67: =VLOOKUP(D67,Sheet1!E:K,6,FALSE) -> 7718237260 | J67: Computer Science | K67: G1 | L67: Dr. Abhishek Singh Verma
A68: 67 | B68: Rinjal Sagar | C68: 2021003785 | D68: 210101586 | E68: B-Tech CSE-VI B | F68: =VLOOKUP(C68,'Fast Track '!B:C,2,FALSE) -> #N/A | G68: Introduction to Internet of Things_CSE071 | H68: 2021003785.rinjal@ug.sharda.ac.in | I68: =VLOOKUP(D68,Sheet1!E:K,6,FALSE) -> 9871907908 | J68: Computer Science | K68: G1 | L68: Dr. Abhishek Singh Verma
A69: 68 | B69: A Vishwam Rao | C69: 2022003574 | D69: 2201010001 | E69: B-Tech CSE-VI B | F69: =VLOOKUP(C69,'Fast Track '!B:C,2,FALSE) -> #N/A | G69: Introduction to Internet of Things_CSE071 | H69: 2022003574.a@ug.sharda.ac.in | I69: =VLOOKUP(D69,Sheet1!E:K,6,FALSE) -> 9971308744 | J69: Computer Science | K69: G1 | L69: Dr. Abhishek Singh Verma
A70: 69 | B70: Abhinay Singh Rawat | C70: 2022360529 | D70: 2201010022 | E70: B-Tech CSE-VI B | F70: =VLOOKUP(C70,'Fast Track '!B:C,2,FALSE) -> #N/A | G70: Introduction to Internet of Things_CSE071 | H70: 2022360529.abhinay@ug.sharda.ac.in | I70: =VLOOKUP(D70,Sheet1!E:K,6,FALSE) -> 7300965989 | J70: Computer Science | K70: G1 | L70: Dr. Abhishek Singh Verma
A71: 70 | B71: Ankit Yadav | C71: 2022538932 | D71: 2201010096 | E71: B-Tech CSE-VI B | F71: =VLOOKUP(C71,'Fast Track '!B:C,2,FALSE) -> #N/A | G71: Introduction to Internet of Things_CSE071 | H71: 2022538932.ankit@ug.sharda.ac.in | I71: =VLOOKUP(D71,Sheet1!E:K,6,FALSE) -> 9625789885 | J71: Computer Science | K71: G1 | L71: Dr. Abhishek Singh Verma
A72: 71 | B72: Anshuman Singh | C72: 2022002787 | D72: 2201010105 | E72: B-Tech CSE-VI B | F72: =VLOOKUP(C72,'Fast Track '!B:C,2,FALSE) -> #N/A | G72: Introduction to Internet of Things_CSE071 | H72: 2022002787.anshuman@ug.sharda.ac.in | I72: =VLOOKUP(D72,Sheet1!E:K,6,FALSE) -> 8707433483 | J72: Computer Science | K72: G1 | L72: Dr. Abhishek Singh Verma
A73: 72 | B73: Anushka Kashyap | C73: 2022005229 | D73: 2201010115 | E73: B-Tech CSE-VI B | F73: =VLOOKUP(C73,'Fast Track '!B:C,2,FALSE) -> #N/A | G73: Introduction to Internet of Things_CSE071 | H73: 2022005229.anushka@ug.sharda.ac.in | I73: =VLOOKUP(D73,Sheet1!E:K,6,FALSE) -> 7827845687 | J73: Computer Science | K73: G1 | L73: Dr. Abhishek Singh Verma
A74: 73 | B74: Aryan Rattan Trakroo | C74: 2022419571 | D74: 2201010146 | E74: B-Tech CSE-VI B | F74: =VLOOKUP(C74,'Fast Track '!B:C,2,FALSE) -> #N/A | G74: Introduction to Internet of Things_CSE071 | H74: 2022419571.aryan@ug.sharda.ac.in | I74: =VLOOKUP(D74,Sheet1!E:K,6,FALSE) -> 9779994998 | J74: Computer Science | K74: G2 | L74: Dr. Abhishek Singh Verma
A75: 74 | B75: Bolla Manoj Sai | C75: 2022433389 | D75: 2201010183 | E75: B-Tech CSE-VI B | F75: =VLOOKUP(C75,'Fast Track '!B:C,2,FALSE) -> #N/A | G75: Introduction to Internet of Things_CSE071 | H75: 2022433389.bolla@ug.sharda.ac.in | I75: =VLOOKUP(D75,Sheet1!E:K,6,FALSE) -> 9492465566 | J75: Computer Science | K75: G1 | L75: Dr. Abhishek Singh Verma
A76: 75 | B76: Brahmtej Mohanty | C76: 2022002578 | D76: 2201010184 | E76: B-Tech CSE-VI B | F76: =VLOOKUP(C76,'Fast Track '!B:C,2,FALSE) -> #N/A | G76: Introduction to Internet of Things_CSE071 | H76: 2022002578.brahmtej@ug.sharda.ac.in | I76: =VLOOKUP(D76,Sheet1!E:K,6,FALSE) -> 7735324362 | J76: Computer Science | K76: G1 | L76: Dr. Abhishek Singh Verma
A77: 76 | B77: Chirag Pathak | C77: 2022005228 | D77: 2201010194 | E77: B-Tech CSE-VI B | F77: =VLOOKUP(C77,'Fast Track '!B:C,2,FALSE) -> #N/A | G77: Introduction to Internet of Things_CSE071 | H77: 2022005228.chirag@ug.sharda.ac.in | I77: =VLOOKUP(D77,Sheet1!E:K,6,FALSE) -> 9267929004 | J77: Computer Science | K77: G1 | L77: Dr. Abhishek Singh Verma
A78: 77 | B78: Danish Kamal | C78: 2022349970 | D78: 2201010201 | E78: B-Tech CSE-VI B | F78: =VLOOKUP(C78,'Fast Track '!B:C,2,FALSE) -> #N/A | G78: Introduction to Internet of Things_CSE071 | H78: 2022349970.danish@ug.sharda.ac.in | I78: =VLOOKUP(D78,Sheet1!E:K,6,FALSE) -> 9873222919 | J78: Computer Science | K78: G1 | L78: Dr. Abhishek Singh Verma
A79: 78 | B79: Jabir Luqman Ismail | C79: 2022804425 | D79: 2201010297 | E79: B-Tech CSE-VI B | F79: =VLOOKUP(C79,'Fast Track '!B:C,2,FALSE) -> #N/A | G79: Introduction to Internet of Things_CSE071 | H79: 2022804425.jabir@ug.sharda.ac.in | I79: =VLOOKUP(D79,Sheet1!E:K,6,FALSE) -> 91 9711260822 | J79: Computer Science | K79: G1 | L79: Dr. Abhishek Singh Verma
... A121: 120 | B121: Avik Roy | C121: 2022836161 | D121: 2201010911 | E121: B-Tech CSE-VI B | F121: =VLOOKUP(C121,'Fast Track '!B:C,2,FALSE) -> #N/A | G121: Introduction to Internet of Things_CSE071 | H121: 2022836161.avik@ug.sharda.ac.in | I121: =VLOOKUP(D121,Sheet1!E:K,6,FALSE) -> 91 9674775066 | J121: Computer Science | K121: G2 | L121: Dr. Abhishek Singh Verma
A122: 121 | B122: Shubh Sahu | C122: 2021361239 | D122: 210101480 | E122: B-Tech CSE-VI B | F122: =VLOOKUP(C122,'Fast Track '!B:C,2,FALSE) -> #N/A | G122: Introduction to Internet of Things_CSE071 | H122: 2021361239.shubh@ug.sharda.ac.in | I122: =VLOOKUP(C122,Sheet1!D:J,7,FALSE) -> 8299431338 | J122: Computer Science | K122: G2 | L122: Dr. Abhishek Singh Verma
A123: 122 | B123: Akim Tartisio Ramdan | C123: 2022826376 | D123: 2201010064 | E123: B-Tech CSE-VI B | F123: =VLOOKUP(C123,'Fast Track '!B:C,2,FALSE) -> #N/A | G123: Introduction to Internet of Things_CSE071 | H123: 2022826376.akim@ug.sharda.ac.in | I123: 91 9910221368 | J123: CSE- IOT & Application | K123: G2 | L123: Dr. Abhishek Singh Verma
A124: 123 | B124: Srishti Singh Chauhan | C124: 2022007474 | D124: 2201010960 | E124: B-Tech CSE-VI B | F124: =VLOOKUP(C124,'Fast Track '!B:C,2,FALSE) -> #N/A | G124: Introduction to Internet of Things_CSE071 | H124: 2022007474.srishti@ug.sharda.ac.in | I124: 9318324541 | J124: CSE- IOT & Application | K124: G2 | L124: Dr. Abhishek Singh Verma
...

Sheet Fast Track 
A1: Sno | B1: System ID | C1: Fasttrack | D1: Campus ID | E1: Student Name | F1: Academic Program | G1: Academic Plan | H1: Remarks | I1: Student's Email | J1: Parent's Email | K1: contact number | L1: Remark-2(Fast Learning Mode)
A2: 1 | B2: 2022498812 | C2: Fasttrack | D2: 2201010796 | E2: Vishal Suryan | F2: Bachelor of Technology | G2: Computer Science | I2: 2022498812.vishal@ug.sharda.ac.in | J2: 2022498812.mukesh@pt.sharda.ac.in | K2: 9910261441 | L2: Fast learning Mode
A3: 2 | B3: 2022003923 | C3: Fasttrack | D3: 2022003923 | E3: Mohammad Shaazan Muzaffar | F3: Bachelor of Technology | G3: Computer Science | I3: 2022003923.mohammad@ug.sharda.ac.in | J3: 2022003923.muzaffarjan@pt.sharda.ac.in | K3: 7006813062 | L3: Fast learning Mode
A4: 3 | B4: 2022418998 | C4: Fasttrack | D4: 2201010756 | E4: Uday B Thakur | F4: Bachelor of Technology | G4: Computer Science | I4: 2022418998.uday@ug.sharda.ac.in | J4: 2022418998.inder@pt.sharda.ac.in | K4: 8076622787 | L4: Fast learning Mode
A5: 4 | B5: 2022506580 | C5: Fasttrack | D5: 2201010556 | E5: Rajesh Ranjan | F5: Bachelor of Technology | G5: Computer Science | I5: 2022506580.rajesh@ug.sharda.ac.in | J5: 2022506580.ramchandra@pt.sharda.ac.in | K5: 6200734740 | L5: Fast learning Mode
A6: 5 | B6: 2022492018 | C6: Fasttrack | D6: 2201010489 | E6: Omit Kumar | F6: Bachelor of Technology | G6: Computer Science | I6: 2022492018.omit@ug.sharda.ac.in | J6: 2022492018.ashokprasad@pt.sharda.ac.in | K6: 8235853597 | L6: Fast learning Mode
A7: 6 | B7: 2022395305 | C7: Fasttrack | D7: 2201010140 | E7: Aryan Kumar | F7: Bachelor of Technology | G7: Computer Science | I7: 2022395305.aryan@ug.sharda.ac.in | J7: 2022395305.rajnish@pt.sharda.ac.in | K7: 9289575803 | L7: Fast learning Mode
A8: 7 | B8: 2022004547 | C8: Fasttrack | D8: 2201010635 | E8: Sanskriti Verma | F8: Bachelor of Technology | G8: Computer Science | I8: 2022004547.sanskriti@ug.sharda.ac.in | J8: 2022004547.sanjay@pt.sharda.ac.in | K8: 7011428007 | L8: Fast learning Mode
A9: 8 | B9: 2022423199 | C9: Fasttrack | D9: 2201010812 | E9: Yash Rawat | F9: Bachelor of Technology | G9: Computer Science | I9: 2022423199.yash@ug.sharda.ac.in | J9: 2022423199.indrasingh@pt.sharda.ac.in | K9: 9871836528 | L9: Fast learning Mode
A10: 9 | B10: 2022552819 | C10: Fasttrack | D10: 2201010005 | E10: Aakriti Bansal | F10: Bachelor of Technology | G10: Computer Science | I10: 2022552819.aakriti@ug.sharda.ac.in | J10: 2022552819.d.k@pt.sharda.ac.in | K10: 8077831479 | L10: Fast learning Mode
A11: 10 | B11: 2022003580 | C11: Fasttrack | D11: 2201010782 | E11: Vedant Tiwari | F11: Bachelor of Technology | G11: Computer Science | I11: 2022003580.vedant@ug.sharda.ac.in | J11: 2022003580.shivram@pt.sharda.ac.in | K11: 9424991187 | L11: Fast learning Mode
A12: 11 | B12: 2022502947 | C12: Fasttrack | D12: 2201010698 | E12: Sneha . | F12: Bachelor of Technology | G12: Computer Science | I12: 2022502947.sneha@ug.sharda.ac.in | J12: 2022502947.jai@pt.sharda.ac.in | K12: 9315149393 | L12: Fast learning Mode
A13: 12 | B13: 2022405479 | C13: Fasttrack | D13: 2201010062 | E13: Akash Rattan | F13: Bachelor of Technology | G13: Computer Science | I13: 2022405479.akash@ug.sharda.ac.in | J13: 2022405479.arvindkumar@pt.sharda.ac.in | K13: 9936616269 | L13: Fast learning Mode
... A39: 38 | B39: 2022004439 | C39: Fasttrack | D39: 2201010221 | E39: Diksha Sharma | F39: Bachelor of Technology | G39: CSE-Cloud Tech & Virtualiz-AWS | I39: 2022004439.diksha@ug.sharda.ac.in | J39: 2022004439.dharmendra@pt.sharda.ac.in | K39: 7827340464 | L39: Fast learning Mode

Sheet A
A1: Sl No. | B1: Student Name | C1: Student System ID | D1: Student Roll No. | E1: New Section | F1: Fast Track | H1: Parent mail id | I1: contact number | J1: Specialization | K1: Group | L1: Mentor
A2: 1 | B2: Anutosh Mishra | C2: 2021308861 | D2: 210101102 | E2: B-Tech CSE-VI A | F2: =VLOOKUP(C2,'Fast Track '!B:C,2,FALSE) -> #N/A | G2: Introduction to Internet of Things_CSE071 | H2: =VLOOKUP(C2,Sheet1!D:J,6,FALSE) -> 2021308861.ashutoshkumar@pt.sharda.ac.in | I2: =VLOOKUP(D2,Sheet1!E:K,6,FALSE) -> 9936777552 | J2: Computer Science | K2: G1 | L2: Ms. Aanchal Vij
A3: 2 | B3: Nandani Chaudhary | C3: 2021828405 | D3: 210101591 | E3: B-Tech CSE-VI A | F3: =VLOOKUP(C3,'Fast Track '!B:C,2,FALSE) -> #N/A | G3: Introduction to Internet of Things_CSE072 | H3: =VLOOKUP(C3,Sheet1!D:J,6,FALSE) -> 2021828405.ramananda@pt.sharda.ac.in | I3: =VLOOKUP(D3,Sheet1!E:K,6,FALSE) -> 8130538380 | J3: Computer Science | K3: G1 | L3: Ms. Aanchal Vij
A4: 3 | B4: Farheen Khan | C4: 2021000009 | D4: 210121021 | E4: B-Tech CSE-VI A | F4: =VLOOKUP(C4,'Fast Track '!B:C,2,FALSE) -> #N/A | G4: Introduction to Internet of Things_CSE073 | H4: =VLOOKUP(C4,Sheet1!D:J,6,FALSE) -> 2021000009.asad@pt.sharda.ac.in | I4: =VLOOKUP(D4,Sheet1!E:K,6,FALSE) -> 9599543010 | J4: Computer Science | K4: G1 | L4: Ms. Aanchal Vij
A5: 4 | B5: Abhiraj Singh | C5: 2022579515 | D5: 2201010023 | E5: B-Tech CSE-VI A | F5: =VLOOKUP(C5,'Fast Track '!B:C,2,FALSE) -> #N/A | G5: Introduction to Internet of Things_CSE074 | H5: =VLOOKUP(C5,Sheet1!D:J,6,FALSE) -> 2022579515.vijaykumar@pt.sharda.ac.in | I5: =VLOOKUP(D5,Sheet1!E:K,6,FALSE) -> 8826793887 | J5: Computer Science | K5: G1 | L5: Ms. Aanchal Vij
A6: 5 | B6: Aman Sinha | C6: 2022534811 | D6: 2201010078 | E6: B-Tech CSE-VI A | F6: =VLOOKUP(C6,'Fast Track '!B:C,2,FALSE) -> #N/A | G6: Introduction to Internet of Things_CSE075 | H6: =VLOOKUP(C6,Sheet1!D:J,6,FALSE) -> 2022534811.rajeshkumar@pt.sharda.ac.in | I6: =VLOOKUP(D6,Sheet1!E:K,6,FALSE) -> 7319641049 | J6: Computer Science | K6: G1 | L6: Ms. Aanchal Vij
A7: 6 | B7: Ansh Shrivastav | C7: 2022475156 | D7: 2201010099 | E7: B-Tech CSE-VI A | F7: =VLOOKUP(C7,'Fast Track '!B:C,2,FALSE) -> #N/A | G7: Introduction to Internet of Things_CSE076 | H7: =VLOOKUP(C7,Sheet1!D:J,6,FALSE) -> 2022475156.dhananjay@pt.sharda.ac.in | I7: =VLOOKUP(D7,Sheet1!E:K,6,FALSE) -> 8789919805 | J7: Computer Science | K7: G1 | L7: Ms. Aanchal Vij
A8: 7 | B8: Anuj Rawat | C8: 2022394343 | D8: 2201010111 | E8: B-Tech CSE-VI A | F8: =VLOOKUP(C8,'Fast Track '!B:C,2,FALSE) -> #N/A | G8: Introduction to Internet of Things_CSE077 | H8: =VLOOKUP(C8,Sheet1!D:J,6,FALSE) -> 2022394343.anandsingh@pt.sharda.ac.in | I8: =VLOOKUP(D8,Sheet1!E:K,6,FALSE) -> 8126133363 | J8: Computer Science | K8: G1 | L8: Ms. Aanchal Vij
A9: 8 | B9: Arbaz Ahmed | C9: 2022006308 | D9: 2201010121 | E9: B-Tech CSE-VI A | F9: =VLOOKUP(C9,'Fast Track '!B:C,2,FALSE) -> #N/A | G9: Introduction to Internet of Things_CSE078 | H9: =VLOOKUP(C9,Sheet1!D:J,6,FALSE) -> 2022006308.asad@pt.sharda.ac.in | I9: =VLOOKUP(D9,Sheet1!E:K,6,FALSE) -> 7300577335 | J9: Computer Science | K9: G1 | L9: Ms. Aanchal Vij
A10: 9 | B10: Atithi Negi | C10: 2022438604 | D10: 2201010162 | E10: B-Tech CSE-VI A | F10: =VLOOKUP(C10,'Fast Track '!B:C,2,FALSE) -> #N/A | G10: Introduction to Internet of Things_CSE079 | H10: =VLOOKUP(C10,Sheet1!D:J,6,FALSE) -> 2022438604.kundansingh@pt.sharda.ac.in | I10: =VLOOKUP(D10,Sheet1!E:K,6,FALSE) -> 8920297350 | J10: Computer Science | K10: G1 | L10: Ms. Aanchal Vij
A11: 10 | B11: Basharat Hassan | C11: 2022521926 | D11: 2201010175 | E11: B-Tech CSE-VI A | F11: =VLOOKUP(C11,'Fast Track '!B:C,2,FALSE) -> #N/A | G11: Introduction to Internet of Things_CSE080 | H11: =VLOOKUP(C11,Sheet1!D:J,6,FALSE) -> 2022521926.ghulamhassan@pt.sharda.ac.in | I11: =VLOOKUP(D11,Sheet1!E:K,6,FALSE) -> 8899544845 | J11: Computer Science | K11: G1 | L11: Ms. Aanchal Vij
A12: 11 | B12: Bhoomi Sharma | C12: 2022325232 | D12: 2201010178 | E12: B-Tech CSE-VI A | F12: =VLOOKUP(C12,'Fast Track '!B:C,2,FALSE) -> #N/A | G12: Introduction to Internet of Things_CSE081 | H12: =VLOOKUP(C12,Sheet1!D:J,6,FALSE) -> 2022325232.latesuneet@pt.sharda.ac.in | I12: =VLOOKUP(D12,Sheet1!E:K,6,FALSE) -> 9717628588 | J12: Computer Science | K12: G1 | L12: Ms. Aanchal Vij
A13: 12 | B13: Chirag Nirwan | C13: 2022305905 | D13: 2201010193 | E13: B-Tech CSE-VI A | F13: =VLOOKUP(C13,'Fast Track '!B:C,2,FALSE) -> #N/A | G13: Introduction to Internet of Things_CSE082 | H13: =VLOOKUP(C13,Sheet1!D:J,6,FALSE) -> 2022305905.sanjeev@pt.sharda.ac.in | I13: =VLOOKUP(D13,Sheet1!E:K,6,FALSE) -> 9311273352 | J13: Computer Science | K13: G1 | L13: Ms. Aanchal Vij
